<?xml version="1.0"?>
<sdf version='1.7'>
  <model name='em_3905'>
    <link name='base_link'>
      <inertial>
        <pose>-0.006634 0 -0.003536 0 -0 0</pose>
        <mass>3.795</mass>
        <inertia>
          <ixx>0.0121404</ixx>
          <ixy>0</ixy>
          <ixz>0.000102071</ixz>
          <iyy>0.0201814</iyy>
          <iyz>0</iyz>
          <izz>0.0301018</izz>
        </inertia>
      </inertial>
      <collision name='base_link_fixed_joint_lump__chassis_collision'>
        <pose>0 0 -0.005 0 -0 0</pose>
        <geometry>
          <box>
            <size>0.258 0.168 0.01</size>
          </box>
        </geometry>
        <surface>
          <contact>
            <ode/>
          </contact>
          <friction>
            <ode/>
          </friction>
        </surface>
      </collision>
      <collision name='base_link_fixed_joint_lump__left_battery_collision_1'>
        <pose>-0.025 0.057319 0.00052 0.349066 -0 0</pose>
        <geometry>
          <box>
            <size>0.16 0.047 0.024</size>
          </box>
        </geometry>
        <surface>
          <contact>
            <ode/>
          </contact>
          <friction>
            <ode/>
          </friction>
        </surface>
      </collision>
      <collision name='base_link_fixed_joint_lump__right_battery_collision_2'>
        <pose>-0.025 -0.057319 0.00052 -0.349066 0 0</pose>
        <geometry>
          <box>
            <size>0.16 0.047 0.024</size>
          </box>
        </geometry>
        <surface>
          <contact>
            <ode/>
          </contact>
          <friction>
            <ode/>
          </friction>
        </surface>
      </collision>
      <visual name='base_link_visual'>
        <pose>0 0 0 0 -0 0</pose>
        <geometry>
          <box>
            <size>0.01 0.01 0.01</size>
          </box>
        </geometry>
        <material>
          <script>
            <name>Gazebo/Grey</name>
            <uri>file://media/materials/scripts/gazebo.material</uri>
          </script>
        </material>
      </visual>
      <visual name='base_link_fixed_joint_lump__chassis_visual_1'>
        <pose>0 0 -0.005 0 -0 0</pose>
        <geometry>
          <box>
            <size>0.258 0.168 0.01</size>
          </box>
        </geometry>
        <material>
          <script>
            <name>Gazebo/Grey</name>
            <uri>file://media/materials/scripts/gazebo.material</uri>
          </script>
        </material>
      </visual>
      <visual name='base_link_fixed_joint_lump__left_battery_visual_2'>
        <pose>-0.025 0.057319 0.00052 0.349066 -0 0</pose>
        <geometry>
          <box>
            <size>0.16 0.047 0.024</size>
          </box>
        </geometry>
        <material>
          <script>
            <name>Gazebo/Blue</name>
            <uri>file://media/materials/scripts/gazebo.material</uri>
          </script>
        </material>
      </visual>
      <visual name='base_link_fixed_joint_lump__right_battery_visual_3'>
        <pose>-0.025 -0.057319 0.00052 -0.349066 0 0</pose>
        <geometry>
          <box>
            <size>0.16 0.047 0.024</size>
          </box>
        </geometry>
        <material>
          <script>
            <name>Gazebo/Blue</name>
            <uri>file://media/materials/scripts/gazebo.material</uri>
          </script>
        </material>
      </visual>
    </link>
    <joint name='left_front_shock' type='prismatic'>
      <pose relative_to='base_link'>0.1675 0.1525 -0.0235 0 -0 0</pose>
      <parent>base_link</parent>
      <child>left_steering_link</child>
      <axis>
        <xyz>0 0 -1</xyz>
        <limit>
          <lower>-0.042</lower>
          <upper>0.042</upper>
          <effort>12.5106</effort>
          <velocity>1000</velocity>
        </limit>
        <dynamics>
          <spring_reference>0</spring_reference>
          <spring_stiffness>0</spring_stiffness>
        </dynamics>
      </axis>
    </joint>
    <link name='left_steering_link'>
      <pose relative_to='left_front_shock'>0 0 0 0 -0 0</pose>
      <inertial>
        <pose>0 0 0 0 -0 0</pose>
        <mass>0.001</mass>
        <inertia>
          <ixx>0.001</ixx>
          <ixy>0</ixy>
          <ixz>0</ixz>
          <iyy>0.001</iyy>
          <iyz>0</iyz>
          <izz>0.001</izz>
        </inertia>
      </inertial>
    </link>
    <joint name='left_steering_joint' type='revolute'>
      <pose relative_to='left_steering_link'>0 0 0 0 -0 0</pose>
      <parent>left_steering_link</parent>
      <child>left_front_axle_carrier</child>
      <axis>
        <xyz>0 0 1</xyz>
        <limit>
          <lower>-0.785398</lower>
          <upper>0.785398</upper>
          <effort>0.5649</effort>
          <velocity>4.553</velocity>
        </limit>
        <dynamics>
          <spring_reference>0</spring_reference>
          <spring_stiffness>0</spring_stiffness>
        </dynamics>
      </axis>
    </joint>
    <link name='left_front_axle_carrier'>
      <pose relative_to='left_steering_joint'>0 0 0 0 -0 0</pose>
      <inertial>
        <pose>0 0 0 0 -0 0</pose>
        <mass>0.001</mass>
        <inertia>
          <ixx>0.001</ixx>
          <ixy>0</ixy>
          <ixz>0</ixz>
          <iyy>0.001</iyy>
          <iyz>0</iyz>
          <izz>0.001</izz>
        </inertia>
      </inertial>
    </link>
    <joint name='left_front_axle' type='revolute'>
      <pose relative_to='left_front_axle_carrier'>0 0 0 1.5708 -0 0</pose>
      <parent>left_front_axle_carrier</parent>
      <child>left_front_wheel</child>
      <axis>
        <xyz>0 0 -1</xyz>
        <limit>
          <effort>5.12766</effort>
          <velocity>244.87</velocity>
          <lower>-1e+16</lower>
          <upper>1e+16</upper>
        </limit>
        <dynamics>
          <spring_reference>0</spring_reference>
          <spring_stiffness>0</spring_stiffness>
        </dynamics>
      </axis>
    </joint>
    <link name='left_front_wheel'>
      <pose relative_to='left_front_axle'>0 0 0 0 -0 0</pose>
      <inertial>
        <pose>0 0 0 0 -0 0</pose>
        <mass>0.29</mass>
        <inertia>
          <ixx>0.000746466</ixx>
          <ixy>0</ixy>
          <ixz>0</ixz>
          <iyy>0.000746466</iyy>
          <iyz>0</iyz>
          <izz>0.00111094</izz>
        </inertia>
      </inertial>
      <collision name='left_front_wheel_collision'>
        <pose>0 -0 0 0 -0 0</pose>
        <geometry>
          <cylinder>
            <length>0.0889</length>
            <radius>0.073025</radius>
          </cylinder>
        </geometry>
        <surface>
          <contact>
            <ode/>
          </contact>
          <friction>
            <ode/>
          </friction>
        </surface>
      </collision>
      <visual name='left_front_wheel_visual'>
        <pose>0 -0 0 0 -0 0</pose>
        <geometry>
          <cylinder>
            <length>0.0889</length>
            <radius>0.073025</radius>
          </cylinder>
        </geometry>
        <material>
          <script>
            <name>Gazebo/Black</name>
            <uri>file://media/materials/scripts/gazebo.material</uri>
          </script>
        </material>
      </visual>
    </link>
    <joint name='left_rear_shock' type='prismatic'>
      <pose relative_to='base_link'>-0.1675 0.1525 -0.0235 0 -0 0</pose>
      <parent>base_link</parent>
      <child>left_rear_axle_carrier</child>
      <axis>
        <xyz>0 0 -1</xyz>
        <limit>
          <lower>-0.042</lower>
          <upper>0.042</upper>
          <effort>12.5106</effort>
          <velocity>1000</velocity>
        </limit>
        <dynamics>
          <spring_reference>0</spring_reference>
          <spring_stiffness>0</spring_stiffness>
        </dynamics>
      </axis>
    </joint>
    <link name='left_rear_axle_carrier'>
      <pose relative_to='left_rear_shock'>0 0 0 0 -0 0</pose>
      <inertial>
        <pose>0 0 0 0 -0 0</pose>
        <mass>0.001</mass>
        <inertia>
          <ixx>0.001</ixx>
          <ixy>0</ixy>
          <ixz>0</ixz>
          <iyy>0.001</iyy>
          <iyz>0</iyz>
          <izz>0.001</izz>
        </inertia>
      </inertial>
    </link>
    <joint name='left_rear_axle' type='revolute'>
      <pose relative_to='left_rear_axle_carrier'>0 0 0 1.5708 -0 0</pose>
      <parent>left_rear_axle_carrier</parent>
      <child>left_rear_wheel</child>
      <axis>
        <xyz>0 0 -1</xyz>
        <limit>
          <effort>5.12766</effort>
          <velocity>244.87</velocity>
          <lower>-1e+16</lower>
          <upper>1e+16</upper>
        </limit>
        <dynamics>
          <spring_reference>0</spring_reference>
          <spring_stiffness>0</spring_stiffness>
        </dynamics>
      </axis>
    </joint>
    <link name='left_rear_wheel'>
      <pose relative_to='left_rear_axle'>0 0 0 0 -0 0</pose>
      <inertial>
        <pose>0 0 0 0 -0 0</pose>
        <mass>0.29</mass>
        <inertia>
          <ixx>0.000746466</ixx>
          <ixy>0</ixy>
          <ixz>0</ixz>
          <iyy>0.000746466</iyy>
          <iyz>0</iyz>
          <izz>0.00111094</izz>
        </inertia>
      </inertial>
      <collision name='left_rear_wheel_collision'>
        <pose>0 -0 0 0 -0 0</pose>
        <geometry>
          <cylinder>
            <length>0.0889</length>
            <radius>0.073025</radius>
          </cylinder>
        </geometry>
        <surface>
          <contact>
            <ode/>
          </contact>
          <friction>
            <ode/>
          </friction>
        </surface>
      </collision>
      <visual name='left_rear_wheel_visual'>
        <pose>0 -0 0 0 -0 0</pose>
        <geometry>
          <cylinder>
            <length>0.0889</length>
            <radius>0.073025</radius>
          </cylinder>
        </geometry>
        <material>
          <script>
            <name>Gazebo/Black</name>
            <uri>file://media/materials/scripts/gazebo.material</uri>
          </script>
        </material>
      </visual>
    </link>
    <joint name='right_front_shock' type='prismatic'>
      <pose relative_to='base_link'>0.1675 -0.1525 -0.0235 0 -0 0</pose>
      <parent>base_link</parent>
      <child>right_steering_link</child>
      <axis>
        <xyz>0 0 -1</xyz>
        <limit>
          <lower>-0.042</lower>
          <upper>0.042</upper>
          <effort>12.5106</effort>
          <velocity>1000</velocity>
        </limit>
        <dynamics>
          <spring_reference>0</spring_reference>
          <spring_stiffness>0</spring_stiffness>
        </dynamics>
      </axis>
    </joint>
    <link name='right_steering_link'>
      <pose relative_to='right_front_shock'>0 0 0 0 -0 0</pose>
      <inertial>
        <pose>0 0 0 0 -0 0</pose>
        <mass>0.001</mass>
        <inertia>
          <ixx>0.001</ixx>
          <ixy>0</ixy>
          <ixz>0</ixz>
          <iyy>0.001</iyy>
          <iyz>0</iyz>
          <izz>0.001</izz>
        </inertia>
      </inertial>
    </link>
    <joint name='right_steering_joint' type='revolute'>
      <pose relative_to='right_steering_link'>0 0 0 0 -0 0</pose>
      <parent>right_steering_link</parent>
      <child>right_front_axle_carrier</child>
      <axis>
        <xyz>0 0 1</xyz>
        <limit>
          <lower>-0.785398</lower>
          <upper>0.785398</upper>
          <effort>0.5649</effort>
          <velocity>4.553</velocity>
        </limit>
        <dynamics>
          <spring_reference>0</spring_reference>
          <spring_stiffness>0</spring_stiffness>
        </dynamics>
      </axis>
    </joint>
    <link name='right_front_axle_carrier'>
      <pose relative_to='right_steering_joint'>0 0 0 0 -0 0</pose>
      <inertial>
        <pose>0 0 0 0 -0 0</pose>
        <mass>0.001</mass>
        <inertia>
          <ixx>0.001</ixx>
          <ixy>0</ixy>
          <ixz>0</ixz>
          <iyy>0.001</iyy>
          <iyz>0</iyz>
          <izz>0.001</izz>
        </inertia>
      </inertial>
    </link>
    <joint name='right_front_axle' type='revolute'>
      <pose relative_to='right_front_axle_carrier'>0 0 0 1.5708 -0 0</pose>
      <parent>right_front_axle_carrier</parent>
      <child>right_front_wheel</child>
      <axis>
        <xyz>0 0 -1</xyz>
        <limit>
          <effort>5.12766</effort>
          <velocity>244.87</velocity>
          <lower>-1e+16</lower>
          <upper>1e+16</upper>
        </limit>
        <dynamics>
          <spring_reference>0</spring_reference>
          <spring_stiffness>0</spring_stiffness>
        </dynamics>
      </axis>
    </joint>
    <link name='right_front_wheel'>
      <pose relative_to='right_front_axle'>0 0 0 0 -0 0</pose>
      <inertial>
        <pose>0 0 0 0 -0 0</pose>
        <mass>0.29</mass>
        <inertia>
          <ixx>0.000746466</ixx>
          <ixy>0</ixy>
          <ixz>0</ixz>
          <iyy>0.000746466</iyy>
          <iyz>0</iyz>
          <izz>0.00111094</izz>
        </inertia>
      </inertial>
      <collision name='right_front_wheel_collision'>
        <pose>0 0 0 0 -0 0</pose>
        <geometry>
          <cylinder>
            <length>0.0889</length>
            <radius>0.073025</radius>
          </cylinder>
        </geometry>
        <surface>
          <contact>
            <ode/>
          </contact>
          <friction>
            <ode/>
          </friction>
        </surface>
      </collision>
      <visual name='right_front_wheel_visual'>
        <pose>0 0 0 0 -0 0</pose>
        <geometry>
          <cylinder>
            <length>0.0889</length>
            <radius>0.073025</radius>
          </cylinder>
        </geometry>
        <material>
          <script>
            <name>Gazebo/Black</name>
            <uri>file://media/materials/scripts/gazebo.material</uri>
          </script>
        </material>
      </visual>
    </link>
    <joint name='right_rear_shock' type='prismatic'>
      <pose relative_to='base_link'>-0.1675 -0.1525 -0.0235 0 -0 0</pose>
      <parent>base_link</parent>
      <child>right_rear_axle_carrier</child>
      <axis>
        <xyz>0 0 -1</xyz>
        <limit>
          <lower>-0.042</lower>
          <upper>0.042</upper>
          <effort>12.5106</effort>
          <velocity>1000</velocity>
        </limit>
        <dynamics>
          <spring_reference>0</spring_reference>
          <spring_stiffness>0</spring_stiffness>
        </dynamics>
      </axis>
    </joint>
    <link name='right_rear_axle_carrier'>
      <pose relative_to='right_rear_shock'>0 0 0 0 -0 0</pose>
      <inertial>
        <pose>0 0 0 0 -0 0</pose>
        <mass>0.001</mass>
        <inertia>
          <ixx>0.001</ixx>
          <ixy>0</ixy>
          <ixz>0</ixz>
          <iyy>0.001</iyy>
          <iyz>0</iyz>
          <izz>0.001</izz>
        </inertia>
      </inertial>
    </link>
    <joint name='right_rear_axle' type='revolute'>
      <pose relative_to='right_rear_axle_carrier'>0 0 0 1.5708 -0 0</pose>
      <parent>right_rear_axle_carrier</parent>
      <child>right_rear_wheel</child>
      <axis>
        <xyz>0 0 -1</xyz>
        <limit>
          <effort>5.12766</effort>
          <velocity>244.87</velocity>
          <lower>-1e+16</lower>
          <upper>1e+16</upper>
        </limit>
        <dynamics>
          <spring_reference>0</spring_reference>
          <spring_stiffness>0</spring_stiffness>
        </dynamics>
      </axis>
    </joint>
    <link name='right_rear_wheel'>
      <pose relative_to='right_rear_axle'>0 0 0 0 -0 0</pose>
      <inertial>
        <pose>0 0 0 0 -0 0</pose>
        <mass>0.29</mass>
        <inertia>
          <ixx>0.000746466</ixx>
          <ixy>0</ixy>
          <ixz>0</ixz>
          <iyy>0.000746466</iyy>
          <iyz>0</iyz>
          <izz>0.00111094</izz>
        </inertia>
      </inertial>
      <collision name='right_rear_wheel_collision'>
        <pose>0 0 0 0 -0 0</pose>
        <geometry>
          <cylinder>
            <length>0.0889</length>
            <radius>0.073025</radius>
          </cylinder>
        </geometry>
        <surface>
          <contact>
            <ode/>
          </contact>
          <friction>
            <ode/>
          </friction>
        </surface>
      </collision>
      <visual name='right_rear_wheel_visual'>
        <pose>0 0 0 0 -0 0</pose>
        <geometry>
          <cylinder>
            <length>0.0889</length>
            <radius>0.073025</radius>
          </cylinder>
        </geometry>
        <material>
          <script>
            <name>Gazebo/Black</name>
            <uri>file://media/materials/scripts/gazebo.material</uri>
          </script>
        </material>
      </visual>
    </link>
    <static>0</static>
    <plugin name='gazebo_ros_control' filename='libgazebo_ros_control.so'/>
  </model>
</sdf>
